<mujoco model="minipi_12dof_250110">
  <compiler angle="radian" meshdir="../meshes/" eulerseq="zyx"/>
  <option timestep='0.001' iterations='50' solver='PGS' gravity='0 0 -9.81'>
    <!-- <flag sensornoise="enable" frictionloss="enable"/> -->
  </option>
  <size njmax="500" nconmax="100" />

  <visual>
    <quality shadowsize='4096'/>
    <map znear='0.05'/>
  </visual>

  <default>
    <joint limited='true'/>
    <motor ctrllimited='true'/>
    <geom condim='4' contype="1" conaffinity="15" solref='0.001 2' friction='0.9 0.2 0.2'/>
    <equality solref='0.001 2'/>
    <default class='visualgeom'>
      <geom material='visualgeom' condim='1' contype='0' conaffinity='0'/>
    </default>
    <default class='visualgeom2'>
      <geom material='visualgeom2' condim='1' contype='0' conaffinity='0'/>
    </default>
    <default class='obstacle'>
      <geom material='obstacle' condim='3' contype='1' conaffinity='15'/>
    </default>
  </default>
  <asset>
    <texture type="skybox" builtin="gradient" rgb1="0.3 0.5 0.7" rgb2="0 0 0" width="512" height="512"/>
    <texture name="texplane" type="2d" builtin="checker" rgb1=".2 .3 .4" rgb2=".1 0.15 0.2" width="512" height="512" mark="cross" markrgb=".8 .8 .8"/>
    <texture name="texplane2" type="2d" builtin="checker" rgb1="1 0.3137 0.1843" rgb2="0.0 0.30196 0.38039" width="512" height="512" mark="cross" markrgb=".8 .8 .8"/>

    <material name="matplane" reflectance="0." texture="texplane" texrepeat="1 1" texuniform="true"/>
    <material name="matplane2" reflectance="0.1" texture="texplane2" texrepeat="1 1" texuniform="true"/>

    <material name='obstacle' rgba='0.9 0.6 0.2 1'/>
    <material name='visualgeom' rgba='0.5 0.9 0.2 1'/>
    <material name='visualgeom2' rgba='0.5 0.9 0.2 1'/>

    <mesh name="base_link" file="base_link.STL"/>
    <mesh name="l_hip_pitch_link" file="l_hip_pitch_link.STL"/>
    <mesh name="l_hip_roll_link" file="l_hip_roll_link.STL"/>
    <mesh name="l_thigh_link" file="l_thigh_link.STL"/>
    <mesh name="l_calf_link" file="l_calf_link.STL"/>
    <mesh name="l_ankle_pitch_link" file="l_ankle_pitch_link.STL"/>
    <mesh name="l_ankle_roll_link" file="l_ankle_roll_link.STL"/>
    <mesh name="r_hip_pitch_link" file="r_hip_pitch_link.STL"/>
    <mesh name="r_hip_roll_link" file="r_hip_roll_link.STL"/>
    <mesh name="r_thigh_link" file="r_thigh_link.STL"/>
    <mesh name="r_calf_link" file="r_calf_link.STL"/>
    <mesh name="r_ankle_pitch_link" file="r_ankle_pitch_link.STL"/>
    <mesh name="r_ankle_roll_link" file="r_ankle_roll_link.STL"/>
    <hfield name='hf0' nrow='200' ncol='200' size="10 5 0.2 .1"/>
  </asset>
  <worldbody>
    <light directional="true" diffuse=".4 .4 .4" specular="0.1 0.1 0.1" pos="0 0 5.0" dir="0 0 -1" castshadow="false"/>
    <light directional="true" diffuse=".6 .6 .6" specular="0.2 0.2 0.2" pos="0 0 4" dir="0 0 -1"/>
    <geom name="ground" type="plane" size="0 0 1" pos="0.001 0 0" quat="1 0 0 0" material="matplane" condim="1" conaffinity='15'/>

    <body name="base_link" pos="0.0 0.0 0.306">
      <inertial pos="0.00110346 0 0.0799838" quat="0.502709 0.497276 0.497276 0.502709" mass="2.4649" diaginertia="0.00400225 0.002861 0.00255266"/>
      <joint type='slide' axis='1 0 0' limited='false' />
      <joint type='slide' axis='0 1 0' limited='false' />
      <joint type='slide' axis='0 0 1' limited='false' />
      <joint type='ball' limited='false' />
      
      <site name='imu' size='0.01' pos='0.0 0 0.0'/>

      <geom type="mesh" contype="0" conaffinity="0" group="1" density="0" rgba="0.89804 0.91765 0.92941 1" mesh="base_link"/>
      <!-- <geom type="mesh" contype="0" conaffinity="0" group="1" density="0" rgba="1 1 1 1" mesh="baselink"/> -->
      <geom type="mesh" rgba="0.89804 0.91765 0.92941 1" mesh="base_link"/>
      <!-- <geom size="0.05 0.05 0.05" pos="0 0 0.08" type="box" rgba="1 1 1 1"/> -->

      <body name="l_hip_pitch_link" pos="0.00214758 0.0437 -0.03225" quat="0.995004 0 -0.0998334 0">
        <inertial pos="-0.00074639 -0.013404 0" quat="0.46664 0.531269 -0.46664 0.531269" mass="0.268402" diaginertia="0.000193 0.000180554 0.000102766"/>
        <joint name="l_hip_pitch_joint" pos="0 0 0" axis="0 1 0" range="-1 0.6"/>
        <geom type="mesh" contype="0" conaffinity="0" group="1" density="0" rgba="0.79216 0.81961 0.93333 1" mesh="l_hip_pitch_link"/>
        <geom size="0.0005 0.0005 0.0005" type="box" rgba="0.79216 0.81961 0.93333 1"/>
        <body name="l_hip_roll_link" pos="0.0235 0.0363 0">
          <inertial pos="-0.023963 0 -0.0030691" quat="0.566834 0.422728 0.422728 0.566834" mass="0.27495" diaginertia="0.0001412 0.000122544 0.000106886"/>
          <joint name="l_hip_roll_joint" pos="0 0 0" axis="1 0 0" range="-0.4 0.4"/>
          <geom type="mesh" contype="0" conaffinity="0" group="1" density="0" rgba="0.79216 0.81961 0.93333 1" mesh="l_hip_roll_link"/>
          <geom size="0.0005 0.0005 0.0005" type="box" rgba="0.79216 0.81961 0.93333 1"/>
          <body name="l_thigh_link" pos="-0.0235 0 -0.0817">
            <inertial pos="0 -0.00069547 0.011181" quat="0.997543 -0.0700559 0 0" mass="0.29535" diaginertia="0.00023194 0.000198545 0.000124555"/>
            <joint name="l_thigh_joint" pos="0 0 0" axis="0 0 1" range="-0.5 0.5"/>
            <geom type="mesh" contype="0" conaffinity="0" group="1" density="0" rgba="0.89804 0.91765 0.92941 1" mesh="l_thigh_link"/>
            <geom size="0.0005 0.0005 0.0005" type="box" rgba="0.89804 0.91765 0.92941 1"/>
            <body name="l_calf_link" pos="0 0.0265 -0.0383" quat="0.972514 0 0.232843 0">
              <inertial pos="0.00071444 -0.0249664 -0.0409766" quat="0.470175 0.52819 0.551393 0.442625" mass="0.590641" diaginertia="0.000412393 0.000412393 0.000412393"/>
              <joint name="l_calf_joint" pos="0 0 0" axis="0 1 0" range="-0.4 1.5"/>
              <geom type="mesh" contype="0" conaffinity="0" group="1" density="0" rgba="0.79216 0.81961 0.93333 1" mesh="l_calf_link"/>
              <geom size="0.0005 0.0005 0.0005" type="box" rgba="0.79216 0.81961 0.93333 1"/>
              <body name="l_ankle_pitch_link" pos="-0.00141263 -0.035 -0.125855" quat="0.990901 0 -0.13459 0">
                <inertial pos="0.0013128 0.0084996 -0.004145" quat="0.5 0.5 0.5 0.5" mass="0.0089231" diaginertia="1.02e-06 9.9e-07 2.3e-07"/>
                <joint name="l_ankle_pitch_joint" pos="0 0 0" axis="0 1 0" range="-0.55 1"/>
                <geom type="mesh" contype="0" conaffinity="0" group="1" density="0" rgba="0.89804 0.91765 0.92941 1" mesh="l_ankle_pitch_link"/>
                <geom size="0.0005 0.0005 0.0005" type="box" rgba="0.89804 0.91765 0.92941 1"/>
                <body name="l_ankle_roll_link" pos="0.0164376 0.0085 -0.00414498">
                  <inertial pos="0.00265884 -3.23e-06 -0.0221598" quat="-1.46905e-05 0.722579 9.73125e-06 0.691288" mass="0.25772" diaginertia="0.000456952 0.00038614 9.81077e-05"/>
                  <joint name="l_ankle_roll_joint" pos="0 0 0" axis="1 0 0" range="-1 1"/>
                  <geom type="mesh" contype="0" conaffinity="0" group="1" density="0" rgba="0.89804 0.91765 0.92941 1" mesh="l_ankle_roll_link"/>
                  <geom type="mesh" rgba="0.89804 0.91765 0.92941 1" mesh="l_ankle_roll_link"/>
                </body>
              </body>
            </body>
          </body>
        </body>
      </body>
      <body name="r_hip_pitch_link" pos="0.00214758 -0.0437 -0.03225" quat="0.995004 0 -0.0998334 0">
        <inertial pos="-0.00074639 0.006036 -1.3436e-10" quat="0.531269 0.46664 -0.531269 0.46664" mass="0.268402" diaginertia="0.000193 0.000180554 0.000102766"/>
        <joint name="r_hip_pitch_joint" pos="0 0 0" axis="0 1 0" range="-1 0.6"/>
        <geom type="mesh" contype="0" conaffinity="0" group="1" density="0" rgba="0.79216 0.81961 0.93333 1" mesh="r_hip_pitch_link"/>
        <geom size="0.0005 0.0005 0.0005" type="box" rgba="0.79216 0.81961 0.93333 1"/>
        <body name="r_hip_roll_link" pos="0.0235 -0.0363 0">
          <inertial pos="-0.023963 0 -0.0030691" quat="0.566834 0.422728 0.422728 0.566834" mass="0.27495" diaginertia="0.0001412 0.000122544 0.000106886"/>
          <joint name="r_hip_roll_joint" pos="0 0 0" axis="1 0 0" range="-0.4 0.4"/>
          <geom type="mesh" contype="0" conaffinity="0" group="1" density="0" rgba="0.79216 0.81961 0.93333 1" mesh="r_hip_roll_link"/>
          <geom size="0.0005 0.0005 0.0005" type="box" rgba="0.79216 0.81961 0.93333 1"/>
          <body name="r_thigh_link" pos="-0.0235 0 -0.0817">
            <inertial pos="0 0.00071139 0.011181" quat="0.997507 0.0705737 0 0" mass="0.29535" diaginertia="0.00023193 0.000198568 0.000124532"/>
            <joint name="r_thigh_joint" pos="0 0 0" axis="0 0 1" range="-0.5 0.5"/>
            <geom type="mesh" contype="0" conaffinity="0" group="1" density="0" rgba="0.89804 0.91765 0.92941 1" mesh="r_thigh_link"/>
            <geom size="0.0005 0.0005 0.0005" type="box" rgba="0.89804 0.91765 0.92941 1"/>
            <body name="r_calf_link" pos="0 -0.0265 -0.0383" quat="0.972514 0 0.232843 0">
              <inertial pos="0.00077628 0.024905 -0.040977" quat="0.703825 0.0119134 -0.023232 0.709894" mass="0.59064" diaginertia="0.000965694 0.000955435 0.000168671"/>
              <joint name="r_calf_joint" pos="0 0 0" axis="0 1 0" range="-0.4 1.5"/>
              <geom type="mesh" contype="0" conaffinity="0" group="1" density="0" rgba="0.79216 0.81961 0.93333 1" mesh="r_calf_link"/>
              <geom size="0.0005 0.0005 0.0005" type="box" rgba="0.79216 0.81961 0.93333 1"/>
              <body name="r_ankle_pitch_link" pos="0 0.0349 -0.13" quat="0.990901 0 -0.13459 0">
                <inertial pos="0 -0.0085004 0" quat="0.5 0.5 0.5 0.5" mass="0.0089231" diaginertia="1.02e-06 9.9e-07 2.3e-07"/>
                <joint name="r_ankle_pitch_joint" pos="0 0 0" axis="0 1 0" range="-0.55 1"/>
                <geom type="mesh" contype="0" conaffinity="0" group="1" density="0" rgba="0.89804 0.91765 0.92941 1" mesh="r_ankle_pitch_link"/>
                <geom size="0.0005 0.0005 0.0005" type="box" rgba="0.89804 0.91765 0.92941 1"/>
                <body name="r_ankle_roll_link" pos="0.015125 -0.0085 -0.0122844">
                  <inertial pos="0.0026588 -3.23e-06 -0.0098754" quat="-1.46905e-05 0.722579 9.73125e-06 0.691288" mass="0.25772" diaginertia="0.000456952 0.00038614 9.81077e-05"/>
                  <joint name="r_ankle_roll_joint" pos="0 0 0" axis="1 0 0" range="-1 1"/>
                  <geom type="mesh" contype="0" conaffinity="0" group="1" density="0" rgba="0.89804 0.91765 0.92941 1" mesh="r_ankle_roll_link"/>
                  <geom type="mesh" rgba="0.89804 0.91765 0.92941 1" mesh="r_ankle_roll_link"/>
                </body>
              </body>
            </body>
          </body>
        </body>
      </body>
    </body>
  </worldbody>
  <actuator>
    <motor name="r_hip_pitch_joint" joint="r_hip_pitch_joint" gear="1" ctrllimited="true" ctrlrange="-200 200"/>
    <motor name="r_hip_roll_joint" joint="r_hip_roll_joint" gear="1" ctrllimited="true" ctrlrange="-200 200"/>
    <motor name="r_thigh_joint" joint="r_thigh_joint" gear="1" ctrllimited="true" ctrlrange="-200 200"/>
    <motor name="r_calf_joint" joint="r_calf_joint" gear="1" ctrllimited="true" ctrlrange="-200 200"/>
    <motor name="r_ankle_pitch_joint" joint="r_ankle_pitch_joint" gear="1" ctrllimited="true" ctrlrange="-200 200"/>
    <motor name="r_ankle_roll_joint" joint="r_ankle_roll_joint" gear="1" ctrllimited="true" ctrlrange="-200 200"/>
    <motor name="l_hip_pitch_joint" joint="l_hip_pitch_joint" gear="1" ctrllimited="true" ctrlrange="-200 200"/>
    <motor name="l_hip_roll_joint" joint="l_hip_roll_joint" gear="1" ctrllimited="true" ctrlrange="-200 200"/>
    <motor name="l_thigh_joint" joint="l_thigh_joint" gear="1" ctrllimited="true" ctrlrange="-200 200"/>
    <motor name="l_calf_joint" joint="l_calf_joint" gear="1" ctrllimited="true" ctrlrange="-200 200"/>
    <motor name="l_ankle_pitch_joint" joint="l_ankle_pitch_joint" gear="1" ctrllimited="true" ctrlrange="-200 200"/>
    <motor name="l_ankle_roll_joint" joint="l_ankle_roll_joint" gear="1" ctrllimited="true" ctrlrange="-200 200"/>
  </actuator>

  <sensor>
    <!-- Position sensors -->
    <actuatorpos name="r_hip_pitch_joint_p" actuator="r_hip_pitch_joint" user="13"/>
    <actuatorpos name="r_hip_roll_joint_p" actuator="r_hip_roll_joint" user="13"/>
    <actuatorpos name="r_thigh_joint_p" actuator="r_thigh_joint" user="13"/>
    <actuatorpos name="r_calf_joint_p" actuator="r_calf_joint" user="13"/>
    <actuatorpos name="r_ankle_pitch_joint_p" actuator="r_ankle_pitch_joint" user="13"/>
    <actuatorpos name="r_ankle_roll_joint_p" actuator="r_ankle_roll_joint" user="13"/>
    <actuatorpos name="l_hip_pitch_joint_p" actuator="l_hip_pitch_joint" user="13"/>
    <actuatorpos name="l_hip_roll_joint_p" actuator="l_hip_roll_joint" user="13"/>
    <actuatorpos name="l_thigh_joint_p" actuator="l_thigh_joint" user="13"/>
    <actuatorpos name="l_calf_joint_p" actuator="l_calf_joint" user="13"/>
    <actuatorpos name="l_ankle_pitch_joint_p" actuator="l_ankle_pitch_joint" user="13"/>
    <actuatorpos name="l_ankle_roll_joint_p" actuator="l_ankle_roll_joint" user="13"/>

    <!-- Velocity sensors -->
    <actuatorvel name="r_hip_pitch_joint_v" actuator="r_hip_pitch_joint" user="13" noise="1e-3"/>
    <actuatorvel name="r_hip_roll_joint_v" actuator="r_hip_roll_joint" user="13" noise="1e-3"/>
    <actuatorvel name="r_thigh_joint_v" actuator="r_thigh_joint" user="13" noise="1e-3"/>
    <actuatorvel name="r_calf_joint_v" actuator="r_calf_joint" user="13" noise="1e-3"/>
    <actuatorvel name="r_ankle_pitch_joint_v" actuator="r_ankle_pitch_joint" user="13" noise="1e-3"/>
    <actuatorvel name="r_ankle_roll_joint_v" actuator="r_ankle_roll_joint" user="13" noise="1e-3"/>
    <actuatorvel name="l_hip_pitch_joint_v" actuator="l_hip_pitch_joint" user="13" noise="1e-3"/>
    <actuatorvel name="l_hip_roll_joint_v" actuator="l_hip_roll_joint" user="13" noise="1e-3"/>
    <actuatorvel name="l_thigh_joint_v" actuator="l_thigh_joint" user="13" noise="1e-3"/>
    <actuatorvel name="l_calf_joint_v" actuator="l_calf_joint" user="13" noise="1e-3"/>
    <actuatorvel name="l_ankle_pitch_joint_v" actuator="l_ankle_pitch_joint" user="13" noise="1e-3"/>
    <actuatorvel name="l_ankle_roll_joint_v" actuator="l_ankle_roll_joint" user="13" noise="1e-3"/>

    <!-- Force sensors -->
    <actuatorfrc name="r_hip_pitch_joint_f" actuator="r_hip_pitch_joint" user="13" noise="1e-3"/>
    <actuatorfrc name="r_hip_roll_joint_f" actuator="r_hip_roll_joint" user="13" noise="1e-3"/>
    <actuatorfrc name="r_thigh_joint_f" actuator="r_thigh_joint" user="13" noise="1e-3"/>
    <actuatorfrc name="r_calf_joint_f" actuator="r_calf_joint" user="13" noise="1e-3"/>
    <actuatorfrc name="r_ankle_pitch_joint_f" actuator="r_ankle_pitch_joint" user="13" noise="1e-3"/>
    <actuatorfrc name="r_ankle_roll_joint_f" actuator="r_ankle_roll_joint" user="13" noise="1e-3"/>
    <actuatorfrc name="l_hip_pitch_joint_f" actuator="l_hip_pitch_joint" user="13" noise="1e-3"/>
    <actuatorfrc name="l_hip_roll_joint_f" actuator="l_hip_roll_joint" user="13" noise="1e-3"/>
    <actuatorfrc name="l_thigh_joint_f" actuator="l_thigh_joint" user="13" noise="1e-3"/>
    <actuatorfrc name="l_calf_joint_f" actuator="l_calf_joint" user="13" noise="1e-3"/>
    <actuatorfrc name="l_ankle_pitch_joint_f" actuator="l_ankle_pitch_joint" user="13" noise="1e-3"/>
    <actuatorfrc name="l_ankle_roll_joint_f" actuator="l_ankle_roll_joint" user="13" noise="1e-3"/>

    <framequat name='orientation' objtype='site' noise='0.001' objname='imu'/>
    <framepos name='position' objtype='site' noise='0.001' objname='imu'/>
    <gyro name='angular-velocity' site='imu' noise='0.005' cutoff='34.9'/>
    <velocimeter name='linear-velocity' site='imu' noise='0.001' cutoff='30'/>
    <accelerometer name='linear-acceleration' site='imu' noise='0.005' cutoff='157'/>
    <magnetometer name='magnetometer' site='imu'/>

  </sensor>
</mujoco>