<?xml version="1.0" encoding="utf-8"?>
<!-- This URDF was automatically created by SolidWorks to URDF Exporter! Originally created by Stephen Brawner (brawner@gmail.com) 
     Commit Version: 1.6.0-4-g7f85cfe  Build Version: 1.6.7995.38578
     For more information, please see http://wiki.ros.org/sw_urdf_exporter -->
<robot name="minipi_12dof_250110">
  <link name="base_link">
    <inertial>
      <origin xyz="0.00110346 0 0.07998382" rpy="0 0 0" />
      <mass value="2.4649" />
      <inertia ixx="0.0025527" ixy="0" ixz="-3.35E-06" iyy="0.00400225" iyz="0" izz="0.00286096" />
    </inertial>
    <visual>
      <origin xyz="0 0 0" rpy="0 0 0" />
      <geometry>
        <mesh filename="package://minipi_12dof_250110/meshes/base_link.STL" />
      </geometry>
      <material name="">
        <color rgba="0.89804 0.91765 0.92941 1" />
      </material>
    </visual>
    <collision>
      <origin xyz="0 0 0" rpy="0 0 0" />
      <geometry>
        <mesh filename="package://minipi_12dof_250110/meshes/base_link.STL" />
      </geometry>
    </collision>
  </link>
  <link name="l_hip_pitch_link">
    <inertial>
      <origin xyz="-0.00074639 -0.01340396 0" rpy="0 0 0" />
      <mass value="0.26840225" />
      <inertia ixx="0.00017926" ixy="9.95E-06" ixz="0" iyy="0.00010406" iyz="0" izz="0.000193" />
    </inertial>
    <visual>
      <origin xyz="0 0 0" rpy="0 0 0" />
      <geometry>
        <mesh filename="package://minipi_12dof_250110/meshes/l_hip_pitch_link.STL" />
      </geometry>
      <material name="">
        <color rgba="0.79216 0.81961 0.93333 1" />
      </material>
    </visual>
    <collision>
      <origin xyz="0 0 0" rpy="0 0 0" />
      <geometry>
        <mesh filename="package://minipi_12dof_250110/meshes/l_hip_pitch_link.STL" />
      </geometry>
    </collision>
  </link>
  <joint name="l_hip_pitch_joint" type="revolute">
    <origin xyz="0.00214758322456313 0.0436999999999998 -0.0322500000000001" rpy="0 0 0" />
    <parent link="base_link" />
    <child link="l_hip_pitch_link" />
    <axis xyz="0 1 0" />
    <limit lower="-1" upper="1" effort="21" velocity="21" />
  </joint>
  <link name="l_hip_roll_link">
    <inertial>
      <origin xyz="-0.023963 0 -0.0030691" rpy="0 0 0" />
      <mass value="0.27495" />
      <inertia ixx="0.00010816" ixy="0" ixz="-4.28E-06" iyy="0.0001412" iyz="0" izz="0.00012127" />
    </inertial>
    <visual>
      <origin xyz="0 0 0" rpy="0 0 0" />
      <geometry>
        <mesh filename="package://minipi_12dof_250110/meshes/l_hip_roll_link.STL" />
      </geometry>
      <material name="">
        <color rgba="0.79216 0.81961 0.93333 1" />
      </material>
    </visual>
    <collision>
      <origin xyz="0 0 0" rpy="0 0 0" />
      <geometry>
        <mesh filename="package://minipi_12dof_250110/meshes/l_hip_roll_link.STL" />
      </geometry>
    </collision>
  </link>
  <joint name="l_hip_roll_joint" type="revolute">
    <origin xyz="0.0235 0.0362999999999998 0" rpy="0 0 0" />
    <parent link="l_hip_pitch_link" />
    <child link="l_hip_roll_link" />
    <axis xyz="1 0 0" />
    <limit lower="-1" upper="1" effort="21" velocity="21" />
  </joint>
  <link name="l_thigh_link">
    <inertial>
      <origin xyz="0 -0.00069547 0.01118105" rpy="0 0 0" />
      <mass value="0.29535" />
      <inertia ixx="0.00023194" ixy="0" ixz="0" iyy="0.0001971" iyz="-1.024E-05" izz="0.000126" />
    </inertial>
    <visual>
      <origin xyz="0 0 0" rpy="0 0 0" />
      <geometry>
        <mesh filename="package://minipi_12dof_250110/meshes/l_thigh_link.STL" />
      </geometry>
      <material name="">
        <color rgba="0.89804 0.91765 0.92941 1" />
      </material>
    </visual>
    <collision>
      <origin xyz="0 0 0" rpy="0 0 0" />
      <geometry>
        <mesh filename="package://minipi_12dof_250110/meshes/l_thigh_link.STL" />
      </geometry>
    </collision>
  </link>
  <joint name="l_thigh_joint" type="revolute">
    <origin xyz="-0.0235 0 -0.0817" rpy="0 0 0" />
    <parent link="l_hip_roll_link" />
    <child link="l_thigh_link" />
    <axis xyz="0 0 1" />
    <limit lower="-1" upper="1" effort="21" velocity="21" />
  </joint>
  <link name="l_calf_link">
    <inertial>
      <origin xyz="0.00071444 -0.0249664 -0.0409766" rpy="0 0 0" />
      <mass value="0.59064065" />
      <inertia ixx="0.00010258" ixy="6.7E-07" ixz="1.148E-05" iyy="0.00096369" iyz="-4.053E-05" izz="0.00017091" />
    </inertial>
    <visual>
      <origin xyz="0 0 0" rpy="0 0 0" />
      <geometry>
        <mesh filename="package://minipi_12dof_250110/meshes/l_calf_link.STL" />
      </geometry>
      <material name="">
        <color rgba="0.79216 0.81961 0.93333 1" />
      </material>
    </visual>
    <collision>
      <origin xyz="0 0 0" rpy="0 0 0" />
      <geometry>
        <mesh filename="package://minipi_12dof_250110/meshes/l_calf_link.STL" />
      </geometry>
    </collision>
  </link>
  <joint name="l_calf_joint" type="revolute">
    <origin xyz="0 0.0264999999999997 -0.0382999999999999" rpy="0 0 0" />
    <parent link="l_thigh_link" />
    <child link="l_calf_link" />
    <axis xyz="0 1 0" />
    <limit lower="-1" upper="1" effort="21" velocity="21" />
  </joint>
  <link name="l_ankle_pitch_link">
    <inertial>
      <origin xyz="0.0013128 0.0084996 -0.004145" rpy="0 0 0" />
      <mass value="0.0089231" />
      <inertia ixx="2.3E-07" ixy="0" ixz="0" iyy="1.02E-06" iyz="0" izz="9.9E-07" />
    </inertial>
    <visual>
      <origin xyz="0 0 0" rpy="0 0 0" />
      <geometry>
        <mesh filename="package://minipi_12dof_250110/meshes/l_ankle_pitch_link.STL" />
      </geometry>
      <material name="">
        <color rgba="0.89804 0.91765 0.92941 1" />
      </material>
    </visual>
    <collision>
      <origin xyz="0 0 0" rpy="0 0 0" />
      <geometry>
        <mesh filename="package://minipi_12dof_250110/meshes/l_ankle_pitch_link.STL" />
      </geometry>
    </collision>
  </link>
  <joint name="l_ankle_pitch_joint" type="revolute">
    <origin xyz="-0.00141263490616071 -0.0349999999999977 -0.12585501881826" rpy="0 0 0" />
    <parent link="l_calf_link" />
    <child link="l_ankle_pitch_link" />
    <axis xyz="0 1 0" />
    <limit lower="-1" upper="1" effort="21" velocity="21" />
  </joint>
  <link name="l_ankle_roll_link">
    <inertial>
      <origin xyz="0.00265884 -3.23E-06 -0.0221598" rpy="0 0 0" />
      <mass value="0.25771965" />
      <inertia ixx="9.881E-05" ixy="-1E-08" ixz="1.586E-05" iyy="0.00038614" iyz="0" izz="0.00045625" />
    </inertial>
    <visual>
      <origin xyz="0 0 0" rpy="0 0 0" />
      <geometry>
        <mesh filename="package://minipi_12dof_250110/meshes/l_ankle_roll_link.STL" />
      </geometry>
      <material name="">
        <color rgba="0.89804 0.91765 0.92941 1" />
      </material>
    </visual>
    <collision>
      <origin xyz="0 0 0" rpy="0 0 0" />
      <geometry>
        <mesh filename="package://minipi_12dof_250110/meshes/l_ankle_roll_link.STL" />
      </geometry>
    </collision>
  </link>
  <joint name="l_ankle_roll_joint" type="revolute">
    <origin xyz="0.0164376349061596 0.00850000000000066 -0.00414498118183187" rpy="0 0 0" />
    <parent link="l_ankle_pitch_link" />
    <child link="l_ankle_roll_link" />
    <axis xyz="1 0 0" />
    <limit lower="-1" upper="1" effort="21" velocity="21" />
  </joint>
  <link name="r_hip_pitch_link">
    <inertial>
      <origin xyz="-0.00074639 0.006036 -1.3436E-10" rpy="0 0 0" />
      <mass value="0.26840225" />
      <inertia ixx="0.00017926" ixy="-9.95E-06" ixz="0" iyy="0.00010406" iyz="0" izz="0.000193" />
    </inertial>
    <visual>
      <origin xyz="0 0 0" rpy="0 0 0" />
      <geometry>
        <mesh filename="package://minipi_12dof_250110/meshes/r_hip_pitch_link.STL" />
      </geometry>
      <material name="">
        <color rgba="0.79216 0.81961 0.93333 1" />
      </material>
    </visual>
    <collision>
      <origin xyz="0 0 0" rpy="0 0 0" />
      <geometry>
        <mesh filename="package://minipi_12dof_250110/meshes/r_hip_pitch_link.STL" />
      </geometry>
    </collision>
  </link>
  <joint name="r_hip_pitch_joint" type="revolute">
    <origin xyz="0.00214758322456313 -0.0437000000000002 -0.0322500000000001" rpy="0 0 0" />
    <parent link="base_link" />
    <child link="r_hip_pitch_link" />
    <axis xyz="0 1 0" />
    <limit lower="-1" upper="1" effort="21" velocity="21" />
  </joint>
  <link name="r_hip_roll_link">
    <inertial>
      <origin xyz="-0.023963 0 -0.0030691" rpy="0 0 0" />
      <mass value="0.27495" />
      <inertia ixx="0.00010816" ixy="0" ixz="-4.28E-06" iyy="0.0001412" iyz="0" izz="0.00012127" />
    </inertial>
    <visual>
      <origin xyz="0 0 0" rpy="0 0 0" />
      <geometry>
        <mesh filename="package://minipi_12dof_250110/meshes/r_hip_roll_link.STL" />
      </geometry>
      <material name="">
        <color rgba="0.79216 0.81961 0.93333 1" />
      </material>
    </visual>
    <collision>
      <origin xyz="0 0 0" rpy="0 0 0" />
      <geometry>
        <mesh filename="package://minipi_12dof_250110/meshes/r_hip_roll_link.STL" />
      </geometry>
    </collision>
  </link>
  <joint name="r_hip_roll_joint" type="revolute">
    <origin xyz="0.0235 -0.0363 0" rpy="0 0 0" />
    <parent link="r_hip_pitch_link" />
    <child link="r_hip_roll_link" />
    <axis xyz="1 0 0" />
    <limit lower="-1" upper="1" effort="21" velocity="21" />
  </joint>
  <link name="r_thigh_link">
    <inertial>
      <origin xyz="0 0.00071139 0.011181" rpy="0 0 0" />
      <mass value="0.29535" />
      <inertia ixx="0.00023193" ixy="0" ixz="0" iyy="0.0001971" iyz="1.032E-05" izz="0.000126" />
    </inertial>
    <visual>
      <origin xyz="0 0 0" rpy="0 0 0" />
      <geometry>
        <mesh filename="package://minipi_12dof_250110/meshes/r_thigh_link.STL" />
      </geometry>
      <material name="">
        <color rgba="0.89804 0.91765 0.92941 1" />
      </material>
    </visual>
    <collision>
      <origin xyz="0 0 0" rpy="0 0 0" />
      <geometry>
        <mesh filename="package://minipi_12dof_250110/meshes/r_thigh_link.STL" />
      </geometry>
    </collision>
  </link>
  <joint name="r_thigh_joint" type="revolute">
    <origin xyz="-0.0235 0 -0.0817" rpy="0 0 0" />
    <parent link="r_hip_roll_link" />
    <child link="r_thigh_link" />
    <axis xyz="0 0 1" />
    <limit lower="-1" upper="1" effort="21" velocity="21" />
  </joint>
  <link name="r_calf_link">
    <inertial>
      <origin xyz="0.00077628 0.024905 -0.040977" rpy="0 0 0" />
      <mass value="0.59064" />
      <inertia ixx="0.00095524" ixy="-7.1E-07" ixz="1.24E-05" iyy="0.00096372" iyz="3.96E-05" izz="0.00017084" />
    </inertial>
    <visual>
      <origin xyz="0 0 0" rpy="0 0 0" />
      <geometry>
        <mesh filename="package://minipi_12dof_250110/meshes/r_calf_link.STL" />
      </geometry>
      <material name="">
        <color rgba="0.79216 0.81961 0.93333 1" />
      </material>
    </visual>
    <collision>
      <origin xyz="0 0 0" rpy="0 0 0" />
      <geometry>
        <mesh filename="package://minipi_12dof_250110/meshes/r_calf_link.STL" />
      </geometry>
    </collision>
  </link>
  <joint name="r_calf_joint" type="revolute">
    <origin xyz="0 -0.0265 -0.0383" rpy="0 0 0" />
    <parent link="r_thigh_link" />
    <child link="r_calf_link" />
    <axis xyz="0 1 0" />
    <limit lower="-1" upper="1" effort="21" velocity="21" />
  </joint>
  <link name="r_ankle_pitch_link">
    <inertial>
      <origin xyz="0 -0.0085004 0" rpy="0 0 0" />
      <mass value="0.0089231" />
      <inertia ixx="2.3E-07" ixy="0" ixz="0" iyy="1.02E-06" iyz="0" izz="9.9E-07" />
    </inertial>
    <visual>
      <origin xyz="0 0 0" rpy="0 0 0" />
      <geometry>
        <mesh filename="package://minipi_12dof_250110/meshes/r_ankle_pitch_link.STL" />
      </geometry>
      <material name="">
        <color rgba="0.89804 0.91765 0.92941 1" />
      </material>
    </visual>
    <collision>
      <origin xyz="0 0 0" rpy="0 0 0" />
      <geometry>
        <mesh filename="package://minipi_12dof_250110/meshes/r_ankle_pitch_link.STL" />
      </geometry>
    </collision>
  </link>
  <joint name="r_ankle_pitch_joint" type="revolute">
    <origin xyz="0 0.0349 -0.130000000000069" rpy="0 0 0" />
    <parent link="r_calf_link" />
    <child link="r_ankle_pitch_link" />
    <axis xyz="0 1 0" />
    <limit lower="-1" upper="1" effort="21" velocity="21" />
  </joint>
  <link name="r_ankle_roll_link">
    <inertial>
      <origin xyz="0.0026588 -3.23E-06 -0.0098754" rpy="0 0 0" />
      <mass value="0.25772" />
      <inertia ixx="9.881E-05" ixy="-1E-08" ixz="1.586E-05" iyy="0.00038614" iyz="0" izz="0.00045625" />
    </inertial>
    <visual>
      <origin xyz="0 0 0" rpy="0 0 0" />
      <geometry>
        <mesh filename="package://minipi_12dof_250110/meshes/r_ankle_roll_link.STL" />
      </geometry>
      <material name="">
        <color rgba="0.89804 0.91765 0.92941 1" />
      </material>
    </visual>
    <collision>
      <origin xyz="0 0 0" rpy="0 0 0" />
      <geometry>
        <mesh filename="package://minipi_12dof_250110/meshes/r_ankle_roll_link.STL" />
      </geometry>
    </collision>
  </link>
  <joint name="r_ankle_roll_joint" type="revolute">
    <origin xyz="0.0151250000000005 -0.00849999999999948 -0.0122844359977193" rpy="0 0 0" />
    <parent link="r_ankle_pitch_link" />
    <child link="r_ankle_roll_link" />
    <axis xyz="1 0 0" />
    <limit lower="-1" upper="1" effort="21" velocity="21" />
  </joint>
</robot>